Workbook

Sheet Portada
B2: RMG AUTO PARTS — Modelo de Negocio por Segmento
B3: Integracion de Matriz Maestra (653 SKU) + Productos por Nicho + Benchmark de Mercado
B4: Santiago, Region Metropolitana - Chile - 2026
B6: Que responde este archivo
B7: Para cada producto priorizado por segmento (52 combinaciones definidas en la hoja Productos_por_Nicho original del usuario), este modelo responde 3 preguntas: que vender, en que presentacion, y que proveedor conviene usar hoy (Cristian Hughes, Vistony o SalfaSur) segun el costo real por unidad normalizada, cruzado contra el precio de mercado de referencia.
B9: Parametros
B10: Margen objetivo B2B RMG (sobre precio de venta) | D10: 0.35
B12: Contenido del libro
B13: - Matriz_Maestra — las 653 SKU de Cristian Hughes, Vistony y SalfaSur con Tipo, Presentacion, Envase y Precio Unitario calculados
B14: - Comparativo_Proveedor — para cada producto priorizado, todas las opciones de proveedor disponibles lado a lado
B15: - Recomendacion_por_Segmento — el resultado final: que vender, en que presentacion, con que proveedor, a que precio, y como queda vs el mercado
B16: - Resumen_Segmento — vista agregada por segmento (cuantos productos, brecha promedio vs mercado)
B17: - Notas — criterios de match usados y productos sin equivalente en el catalogo actual

Sheet Matriz_Maestra
A1: Proveedor | B1: Marca | C1: Categoria | D1: Codigo | E1: Descripcion Original | F1: Precio Original Contado (CLP) | G1: Precio Original Credito (CLP) | H1: Tipo | I1: Presentacion (volumen) | J1: Envase | K1: Contenido Normalizado | L1: Unidad | M1: Cantidad x Caja (Q) | N1: Precio Unitario (CLP) | O1: Precio Unitario Normalizado (CLP/L, CLP/Kg o CLP/Un) | P1: Stock (si aplica) | Q1: Nota
A2: Vistony | B2: Vistony | C2: Lubricante | D2: 1000544 | E2: CAJ04 ATTOM S320 SAE 5W-30 ACEA C3/API SN DE 5 L | F2: 87780 | G2: 93046 | H2: ATTOM S320 SAE 5W-30 | I2: 5 L | J2: Bidon | K2: 5 | L2: L | M2: 4 | N2: =F2/M2 -> 21945 | O2: =N2/K2 -> 4389
A3: Vistony | B3: Vistony | C3: Refrigerante/Aditivo Diesel | D3: 1200009 | E3: CAJ06 LIQUIDO PARA RADIADOR VERDE DE 1 GAL | F3: 15254 | G3: 16169 | H3: LIQUIDO PARA RADIADOR VERDE | I3: 1 GAL | J3: Galon | K3: 3.785 | L3: L | M3: 6 | N3: =F3/M3 -> 2542.3333 | O3: =N3/K3 -> 671.68648
A4: Vistony | B4: Vistony | C4: Lubricante | D4: 1000560 | E4: CAJ04 SINTEK OIL S 210 SAE 10W40 ACEA A3/B4 - API SN DE 4L | F4: 67674 | G4: 71735 | H4: SINTEK OIL S 210 SAE 10W40 | I4: 4 L | J4: Galon | K4: 4 | L4: L | M4: 4 | N4: =F4/M4 -> 16918.5 | O4: =N4/K4 -> 4229.625
A5: Vistony | B5: Vistony | C5: Refrigerante/Aditivo Diesel | D5: 1200105 | E5: CAJ06 COOLANT ICE FREEZE ORGANIC (OAT) 50/50 GREEN - 5 IDIOMAS DE 4L | F5: 54652 | G5: 57931 | H5: COOLANT ICE FREEZE ORGANIC (OAT) 50/50 GREEN - 5 IDIOMAS | I5: 4 L | J5: Galon | K5: 4 | L5: L | M5: 6 | N5: =F5/M5 -> 9108.6667 | O5: =N5/K5 -> 2277.1667
A6: Vistony | B6: Vistony | C6: Lubricante | D6: 1000618 | E6: CAJ12 TRANSMEC SYNTHETIC API GL-4 SAE 75W90 DE 1L | F6: 69392 | G6: 73555 | H6: TRANSMEC SYNTHETIC SAE 75W90 | I6: 1 L | J6: Frasco/Botella | K6: 1 | L6: L | M6: 12 | N6: =F6/M6 -> 5782.6667 | O6: =N6/K6 -> 5782.6667
A7: Vistony | B7: Vistony | C7: Refrigerante/Aditivo Diesel | D7: 1200083 | E7: CAJ06 COOLANT ICE FREEZE ORGANICO (OAT) 50/50 LONG LIFE FUCHSIA DE 4L | F7: 54201 | G7: 57453 | H7: COOLANT ICE FREEZE ORGANICO (OAT) 50/50 LONG LIFE FUCHSIA | I7: 4 L | J7: Galon | K7: 4 | L7: L | M7: 6 | N7: =F7/M7 -> 9033.5 | O7: =N7/K7 -> 2258.375
A8: Vistony | B8: Vistony | C8: Lubricante | D8: 1000738 | E8: BAL DRAULA H 68 DE 5 GL | F8: 47502 | G8: 50353 | H8: DRAULA H 68 | I8: 5 GL | J8: Balde | K8: 18.925 | L8: L | M8: 1 | N8: =F8/M8 -> 47502 | O8: =N8/K8 -> 2510.0132
A9: Vistony | B9: Vistony | C9: Lubricante | D9: 1000045 | E9: CAJ12 TRANSMISION AUTOMATICA - ATF DE 1/4 GL | F9: 55593 | G9: 58928 | H9: TRANSMISION AUTOMATICA - ATF | I9: 1/4 GL | J9: Frasco/Botella | K9: 0.9463 | L9: L | M9: 12 | N9: =F9/M9 -> 4632.75 | O9: =N9/K9 -> 4895.6462
A10: Vistony | B10: Vistony | C10: Lubricante | D10: 1000545 | E10: CIL ATTOM S320 SAE 5W-30 ACEA C3/API SN DE 55 GL | F10: 810806 | G10: 859454 | H10: ATTOM S320 SAE 5W-30 | I10: 55 GL | J10: Tambor/Cilindro | K10: 208.175 | L10: L | M10: 1 | N10: =F10/M10 -> 810806 | O10: =N10/K10 -> 3894.8289
A11: Vistony | B11: Vistony | C11: Lubricante | D11: 1000130 | E11: CAJ12 GEAR OIL GL-5 SAE 80W90 DE 0.946 LT | F11: 53635 | G11: 56853 | H11: GEAR OIL GL-5 SAE 80W90 | I11: 0.946 LT | J11: Frasco/Botella | K11: 0.946 | L11: L | M11: 12 | N11: =F11/M11 -> 4469.5833 | O11: =N11/K11 -> 4724.7181
A12: Vistony | B12: Vistony | C12: Lubricante | D12: 1000806 | E12: CAJ06 BLINDAX DUO SAE 10W40 DE 4 LT | F12: 72793 | G12: 77160 | H12: BLINDAX DUO SAE 10W40 | I12: 4 LT | J12: Galon | K12: 4 | L12: L | M12: 6 | N12: =F12/M12 -> 12132.167 | O12: =N12/K12 -> 3033.0417
A13: Vistony | B13: Vistony | C13: Refrigerante/Aditivo Diesel | D13: 1200079 | E13: CAJ06 COOLANT ICE FREEZE ORGANICO (OAT) 33% GREEN DE 1 GL | F13: 43747 | G13: 46371 | H13: COOLANT ICE FREEZE ORGANICO (OAT) 33% GREEN | I13: 1 GL | J13: Galon | K13: 3.785 | L13: L | M13: 6 | N13: =F13/M13 -> 7291.1667 | O13: =N13/K13 -> 1926.332
... A65: Vistony | B65: Vistony | C65: Grasa | D65: 1100290 | E65: CAJ12 GRAFITADA PARA PALIERES DE 210 GRS | F65: 15682 | G65: 16623 | H65: GRAFITADA PARA PALIERES | I65: 210 GRS | J65: Tarro | K65: 0.21 | L65: KG | M65: 12 | N65: =F65/M65 -> 1306.8333 | O65: =N65/K65 -> 6223.0159
A66: Vistony | B66: Vistony | C66: Lubricante | D66: 1000786 | E66: LIT DRAULA H 68 | F66: 1981 | G66: 2100 | H66: DRAULA H 68 | I66: 1 L | J66: Frasco/Botella | K66: 1 | L66: L | M66: 1 | N66: =F66/M66 -> 1981 | O66: =N66/K66 -> 1981 | Q66: LIT = suelto, asumido 1L
A67: Vistony | B67: Vistony | C67: Lubricante | D67: 1000779 | E67: CAJ12 RAYVON FORK OIL 10W DE 1 L | F67: 57964 | G67: 61442 | H67: RAYVON FORK OIL 10W | I67: 1 L | J67: Frasco/Botella | K67: 1 | L67: L | M67: 12 | N67: =F67/M67 -> 4830.3333 | O67: =N67/K67 -> 4830.3333
A68: Vistony | B68: Vistony | C68: Lubricante | D68: 1000839 | E68: CIL FORZA TRUCK SAE 20W-50 DE 55 GAL | F68: 537969 | G68: 570247 | H68: FORZA TRUCK SAE 20W-50 | I68: 55 GAL | J68: Tambor/Cilindro | K68: 208.175 | L68: L | M68: 1 | N68: =F68/M68 -> 537969 | O68: =N68/K68 -> 2584.2152
A69: Vistony | B69: Vistony | C69: Lubricante | D69: 1000708 | E69: BAL VELTRON ISO VG 680 DE 5 GAL | F69: 65799 | G69: 69747 | H69: VELTRON ISO VG 680 | I69: 5 GAL | J69: Balde | K69: 18.925 | L69: L | M69: 1 | N69: =F69/M69 -> 65799 | O69: =N69/K69 -> 3476.8296
A70: Vistony | B70: Vistony | C70: Grasa | D70: 1100276 | E70: CAJ24 EP-2 LITHIUM MULTIPROPOSITO ROJO DE 210 GRS | F70: 30055 | G70: 31858 | H70: EP-2 LITHIUM MULTIPROPOSITO ROJO | I70: 210 GRS | J70: Tarro | K70: 0.21 | L70: KG | M70: 24 | N70: =F70/M70 -> 1252.2917 | O70: =N70/K70 -> 5963.2937
A71: Vistony | B71: Vistony | C71: Lubricante | D71: 1000127 | E71: CAJ12 GEAR OIL GL-5 SAE 85W140 DE 0.946 LT | F71: 50468 | G71: 53496 | H71: GEAR OIL GL-5 SAE 85W140 | I71: 0.946 LT | J71: Frasco/Botella | K71: 0.946 | L71: L | M71: 12 | N71: =F71/M71 -> 4205.6667 | O71: =N71/K71 -> 4445.7364
A72: Vistony | B72: Vistony | C72: Lubricante | D72: 1000083 | E72: BAL DRAULA H 46 DE 5 GAL | F72: 45086 | G72: 47791 | H72: DRAULA H 46 | I72: 5 GAL | J72: Balde | K72: 18.925 | L72: L | M72: 1 | N72: =F72/M72 -> 45086 | O72: =N72/K72 -> 2382.3514
A73: Vistony | B73: Vistony | C73: Quimico/Cuidado vehicular | D73: 1400079 | E73: CAJ12 LIMPIA RADIADOR DE LATA DE 300 ML | F73: 34467 | G73: 36535 | H73: LIMPIA RADIADOR DE LATA | I73: 300 ML | J73: Sachet/Spray | K73: 0.3 | L73: L | M73: 12 | N73: =F73/M73 -> 2872.25 | O73: =N73/K73 -> 9574.1667
A74: Vistony | B74: Vistony | C74: Lubricante | D74: 1000440 | E74: BAL FORZA VIS SAE 25W60 API CF-4 DE 5 GAL | F74: 59317 | G74: 62876 | H74: FORZA VIS SAE 25W60 | I74: 5 GAL | J74: Balde | K74: 18.925 | L74: L | M74: 1 | N74: =F74/M74 -> 59317 | O74: =N74/K74 -> 3134.3197
A75: Vistony | B75: Vistony | C75: Lubricante | D75: 1000143 | E75: CIL GEAR OIL GL-5 SAE 80W90 DE 55 GL | F75: 696805 | G75: 738613 | H75: GEAR OIL GL-5 SAE 80W90 | I75: 55 GL | J75: Tambor/Cilindro | K75: 208.175 | L75: L | M75: 1 | N75: =F75/M75 -> 696805 | O75: =N75/K75 -> 3347.2079
A76: Vistony | B76: Vistony | C76: Grasa | D76: 1100284 | E76: BAL COMPLEJO DE LITIO NLGI 2 DE 35 LIBRAS | F76: 74907 | G76: 79401 | H76: COMPLEJO DE LITIO NLGI 2 | I76: 35 LIBRAS | J76: Balde | K76: 15.8757 | L76: KG | M76: 1 | N76: =F76/M76 -> 74907 | O76: =N76/K76 -> 4718.3431
A77: Vistony | B77: Vistony | C77: Aditivo | D77: 1600002 | E77: CAJ12 ADITIVO ESPECIAL PARA DIESEL DE 443 ML | F77: 35078 | G77: 37183 | H77: ADITIVO ESPECIAL PARA DIESEL | I77: 443 ML | J77: Frasco/Botella | K77: 0.443 | L77: L | M77: 12 | N77: =F77/M77 -> 2923.1667 | O77: =N77/K77 -> 6598.5704
A78: Vistony | B78: Vistony | C78: Lubricante | D78: 1200141 | E78: CAJ06 AGUA P/ BATERIA DE 1 GAL | F78: 12550 | G78: 13303 | H78: AGUA P/ BATERIA | I78: 1 GAL | J78: Galon | K78: 3.785 | L78: L | M78: 6 | N78: =F78/M78 -> 2091.6667 | O78: =N78/K78 -> 552.61999
... A279: Vistony | B279: Vistony | C279: Grasa | D279: 1100045 | E279: CAJ12 EP-2 LITHIUM MULTIPROPOSITO ROJO DE 453 GRS | F279: 28897 | G279: 30631 | H279: EP-2 LITHIUM MULTIPROPOSITO ROJO | I279: 453 GRS | J279: Tarro | K279: 0.453 | L279: KG | M279: 12 | N279: =F279/M279 -> 2408.0833 | O279: =N279/K279 -> 5315.8572
A280: Vistony | B280: Vistony | C280: Grasa | D280: 1100130 | E280: CIL COMPLEJO DE LITIO NLGI 2 CILINDRO | F280: 1268883 | G280: 1345016 | H280: COMPLEJO DE LITIO NLGI 2 CILINDRO | I280: Cilindro/Tambor | J280: Tambor/Cilindro | M280: 1 | N280: =F280/M280 -> 1268883 | Q280: Sin dato de volumen - revisar manualmente
A281: Vistony | B281: Vistony | C281: Grasa | D281: 1100138 | E281: CAJ12 EP-2 LITHIUM MULTIPROPOSITO AMARILLO DE 210 GRS | F281: 13677 | G281: 14497 | H281: EP-2 LITHIUM MULTIPROPOSITO AMARILLO | I281: 210 GRS | J281: Tarro | K281: 0.21 | L281: KG | M281: 12 | N281: =F281/M281 -> 1139.75 | O281: =N281/K281 -> 5427.381
A282: Vistony | B282: Vistony | C282: Grasa | D282: 1100141 | E282: CAJ12 GRAFITADA PARA PALIERES DE 210 GRS | F282: 14292 | G282: 15149 | H282: GRAFITADA PARA PALIERES | I282: 210 GRS | J282: Tarro | K282: 0.21 | L282: KG | M282: 12 | N282: =F282/M282 -> 1191 | O282: =N282/K282 -> 5671.4286
A283: Vistony | B283: Vistony | C283: Grasa | D283: 1100142 | E283: CAJ24 GRAFITADA PARA PALIERES DE 210 GRS | F283: 28584 | G283: 30299 | H283: GRAFITADA PARA PALIERES | I283: 210 GRS | J283: Tarro | K283: 0.21 | L283: KG | M283: 24 | N283: =F283/M283 -> 1191 | O283: =N283/K283 -> 5671.4286
A284: Vistony | B284: Vistony | C284: Grasa | D284: 1100144 | E284: CAJ12 EP-2 LITHIUM MULTIPROPOSITO ROJO DE 210 GRS | F284: 13677 | G284: 14497 | H284: EP-2 LITHIUM MULTIPROPOSITO ROJO | I284: 210 GRS | J284: Tarro | K284: 0.21 | L284: KG | M284: 12 | N284: =F284/M284 -> 1139.75 | O284: =N284/K284 -> 5427.381
A285: Vistony | B285: Vistony | C285: Grasa | D285: 1100145 | E285: CAJ24 EP-2 LITHIUM MULTIPROPOSITO ROJO DE 210 GRS | F285: 25250 | G285: 26765 | H285: EP-2 LITHIUM MULTIPROPOSITO ROJO | I285: 210 GRS | J285: Tarro | K285: 0.21 | L285: KG | M285: 24 | N285: =F285/M285 -> 1052.0833 | O285: =N285/K285 -> 5009.9206
A286: Vistony | B286: Vistony | C286: Grasa | D286: 1100153 | E286: CAJ12 H-3 PARA RODAMIENTOS ROJO DE 210 GRS | F286: 12698 | G286: 13460 | H286: H-3 PARA RODAMIENTOS ROJO | I286: 210 GRS | J286: Tarro | K286: 0.21 | L286: KG | M286: 12 | N286: =F286/M286 -> 1058.1667 | O286: =N286/K286 -> 5038.8889
A287: Vistony | B287: Vistony | C287: Grasa | D287: 1100198 | E287: CIL COMPLEX MOLY NLGI 2 DE 400 LB | F287: 1335552 | G287: 1415685 | H287: COMPLEX MOLY NLGI 2 | I287: 400 LB | J287: Tambor/Cilindro | K287: 181.4368 | L287: KG | M287: 1 | N287: =F287/M287 -> 1335552 | O287: =N287/K287 -> 7360.9764
A288: Vistony | B288: Vistony | C288: Grasa | D288: 1100263 | E288: CAJ24 EP-2 LITHIUM MULTIPROPOSITO AMARILLO DE 210 GRS | F288: 22156 | G288: 23486 | H288: EP-2 LITHIUM MULTIPROPOSITO AMARILLO | I288: 210 GRS | J288: Tarro | K288: 0.21 | L288: KG | M288: 24 | N288: =F288/M288 -> 923.16667 | O288: =N288/K288 -> 4396.0317
A289: Vistony | B289: Vistony | C289: Refrigerante/Aditivo Diesel | D289: 1200010 | E289: GL LIQUIDO PARA RADIADOR VERDE DE 1 GAL | F289: 2370 | G289: 2512 | H289: LIQUIDO PARA RADIADOR VERDE | I289: 1 GAL | J289: Galon | K289: 3.785 | L289: L | M289: 1 | N289: =F289/M289 -> 2370 | O289: =N289/K289 -> 626.15588
A290: Vistony | B290: Vistony | C290: Refrigerante/Aditivo Diesel | D290: 1200024 | E290: FRA LIQUIDO PARA RADIADOR DE 1/4 GL | F290: 715 | G290: 758 | H290: LIQUIDO PARA RADIADOR | I290: 1/4 GL | J290: Frasco/Botella | K290: 0.9463 | L290: L | M290: 1 | N290: =F290/M290 -> 715 | O290: =N290/K290 -> 755.57434
A291: Vistony | B291: Vistony | C291: Grasa | D291: 1100271 | E291: CIL COMPLEX MOLY NLGI 2 DE 400 LB | F291: 1335552 | G291: 1415685 | H291: COMPLEX MOLY NLGI 2 | I291: 400 LB | J291: Tambor/Cilindro | K291: 181.4368 | L291: KG | M291: 1 | N291: =F291/M291 -> 1335552 | O291: =N291/K291 -> 7360.9764
...

Sheet Comparativo_Proveedor
A1: Categoria | B1: Producto (spec) | C1: Segmento | D1: Proveedor | E1: Marca | F1: Codigo SKU | G1: Descripcion SKU | H1: Presentacion | I1: Envase | J1: Costo Unitario (CLP/L, CLP/Kg o CLP/Un) | K1: Mas conveniente
A2: Baterias | B2: Bateria 100 Ah | C2: Construccion (agro) | D2: Cristian Hughes | E2: Platin | F2: PT105D31R | G2: 105D31R (90 Ah - 640 CCA) | H2: Unidad | I2: Unidad | J2: 53900 | K2: SI - mas barato
A3: Baterias | B3: Bateria 100 Ah | C3: Construccion (agro) | D3: SalfaSur | E3: YOKO G&B | F3: 352438 | G3: BATERIA YOKO KR 90AMP NX120-7 | H3: Unidad | I3: Unidad | J3: 69715.2
A4: Baterias | B4: Bateria 120 Ah | C4: Construccion (agro) | D4: Cristian Hughes | E4: Platin | F4: PT120 | G4: N120 (120 Ah - 760 CCA) | H4: Unidad | I4: Unidad | J4: 89990 | K4: SI - mas barato
A5: Baterias | B5: Bateria 120 Ah | C5: Construccion (agro) | D5: SalfaSur | E5: YOKO G&B | F5: 352445 | G5: BATERIA YOKO KR 120AMP N120 | H5: Unidad | I5: Unidad | J5: 100573.4
A6: Baterias | B6: Bateria 150 Ah | C6: Flotas / Construccion | D6: Cristian Hughes | E6: Platin | F6: PT150 | G6: N150 (150 Ah - 1000 CCA) | H6: Unidad | I6: Unidad | J6: 104990 | K6: SI - mas barato
A7: Baterias | B7: Bateria 150 Ah | C7: Flotas / Construccion | D7: SalfaSur | E7: YOKO G&B | F7: 352450 | G7: BATERIA YOKO KR 150AMP N150 | H7: Unidad | I7: Unidad | J7: 129164.3
A8: Baterias | B8: Bateria 150 Ah agro | C8: Construccion (agro) | D8: Cristian Hughes | E8: Platin | F8: PT150 | G8: N150 (150 Ah - 1000 CCA) | H8: Unidad | I8: Unidad | J8: 104990 | K8: SI - mas barato
A9: Baterias | B9: Bateria 150 Ah agro | C9: Construccion (agro) | D9: SalfaSur | E9: YOKO G&B | F9: 352450 | G9: BATERIA YOKO KR 150AMP N150 | H9: Unidad | I9: Unidad | J9: 129164.3
A10: Baterias | B10: Bateria 180 Ah | C10: Flotas / Construccion | D10: Cristian Hughes | E10: Platin | F10: PT180 | G10: N180 (180 Ah - 1100 CCA) | H10: Unidad | I10: Unidad | J10: 119990 | K10: SI - mas barato
A11: Baterias | B11: Bateria 180 Ah agro | C11: Construccion (agro) | D11: Cristian Hughes | E11: Platin | F11: PT180 | G11: N180 (180 Ah - 1100 CCA) | H11: Unidad | I11: Unidad | J11: 119990 | K11: SI - mas barato
A12: Baterias | B12: Bateria 200 Ah | C12: Flotas / Construccion | D12: Cristian Hughes | E12: Platin | F12: PT200 | G12: N200 (200 Ah - 1100 CCA) | H12: Unidad | I12: Unidad | J12: 119990 | K12: SI - mas barato
A13: Baterias | B13: Bateria 200 Ah | C13: Flotas / Construccion | D13: SalfaSur | E13: YOKO G&B | F13: 352465 | G13: BATERIA YOKO KR 200AMP N200 | H13: Unidad | I13: Unidad | J13: 170703.8
A14: Baterias | B14: Bateria 45 Ah | C14: Talleres / Concesionarios | D14: SalfaSur | E14: YOKO G&B | F14: 352410 | G14: BATERIA YOKO KR 35AMP NS40ZL | H14: Unidad | I14: Unidad | J14: 31310.5 | K14: SI - mas barato
A15: Baterias | B15: Bateria 45 Ah | C15: Talleres / Concesionarios | D15: Cristian Hughes | E15: Platin | F15: PT40B19L | G15: 40B19L (35 Ah - 300 CCA) | H15: Unidad | I15: Unidad | J15: 31500
A16: Baterias | B16: Bateria 55 Ah | C16: Talleres / Concesionarios | D16: Cristian Hughes | E16: Platin | F16: PT55566 | G16: 55566 (55 Ah - 390 CCA) | H16: Unidad | I16: Unidad | J16: 31500 | K16: SI - mas barato
A17: Baterias | B17: Bateria 55 Ah | C17: Talleres / Concesionarios | D17: SalfaSur | E17: YOKO G&B | F17: 352447 | G17: BATERIA YOKO KR 45AMP NX100-S6LS | H17: Unidad | I17: Unidad | J17: 41703.4
A18: Baterias | B18: Bateria 60 Ah | C18: Talleres / Concesionarios | D18: Cristian Hughes | E18: Platin | F18: PT55566 | G18: 55566 (55 Ah - 390 CCA) | H18: Unidad | I18: Unidad | J18: 31500 | K18: SI - mas barato
A19: Baterias | B19: Bateria 60 Ah | C19: Talleres / Concesionarios | D19: SalfaSur | E19: YOKO G&B | F19: 352466 | G19: BATERIA YOKO KR 55AMP 55565 | H19: Unidad | I19: Unidad | J19: 44272.3
A20: Baterias | B20: Bateria 65 Ah | C20: Talleres / Concesionarios | D20: Cristian Hughes | E20: Platin | F20: PT55566 | G20: 55566 (55 Ah - 390 CCA) | H20: Unidad | I20: Unidad | J20: 31500 | K20: SI - mas barato
A21: Baterias | B21: Bateria 65 Ah | C21: Talleres / Concesionarios | D21: SalfaSur | E21: YOKO G&B | F21: 352466 | G21: BATERIA YOKO KR 55AMP 55565 | H21: Unidad | I21: Unidad | J21: 44272.3
A22: Baterias | B22: Bateria 70 Ah | C22: Talleres / Concesionarios | D22: Cristian Hughes | E22: Platin | F22: PT55D23L | G22: 55D23L (60 Ah - 500 CCA) | H22: Unidad | I22: Unidad | J22: 40500 | K22: SI - mas barato
A23: Baterias | B23: Bateria 70 Ah | C23: Talleres / Concesionarios | D23: SalfaSur | E23: YOKO G&B | F23: 352460 | G23: SMF 56219 62AMP CCA510 | H23: Unidad | I23: Unidad | J23: 47167.6
A24: Baterias | B24: Bateria 75 Ah | C24: Talleres / Concesionarios / Flotas | D24: Cristian Hughes | E24: Platin | F24: PT85D26L | G24: 85D26L (70 Ah - 550 CCA) | H24: Unidad | I24: Unidad | J24: 43990 | K24: SI - mas barato
A25: Baterias | B25: Bateria 75 Ah | C25: Talleres / Concesionarios / Flotas | D25: SalfaSur | E25: YOKO G&B | F25: 352436 | G25: BATERIA YOKO KR 70AMP NX110-5L | H25: Unidad | I25: Unidad | J25: 59234.7
A26: Baterias | B26: Bateria 80 Ah | C26: Talleres / Concesionarios / Flotas | D26: Cristian Hughes | E26: Platin | F26: PT85D26L | G26: 85D26L (70 Ah - 550 CCA) | H26: Unidad | I26: Unidad | J26: 43990 | K26: SI - mas barato
A27: Baterias | B27: Bateria 80 Ah | C27: Talleres / Concesionarios / Flotas | D27: SalfaSur | E27: YOKO G&B | F27: 352436 | G27: BATERIA YOKO KR 70AMP NX110-5L | H27: Unidad | I27: Unidad | J27: 59234.7
A28: Baterias | B28: Bateria 90 Ah | C28: Talleres / Concesionarios / Flotas | D28: Cristian Hughes | E28: Platin | F28: PT90D26L | G28: 90D26L (80 Ah - 620 CCA) | H28: Unidad | I28: Unidad | J28: 52500 | K28: SI - mas barato
A29: Baterias | B29: Bateria 90 Ah | C29: Talleres / Concesionarios / Flotas | D29: SalfaSur | E29: YOKO G&B | F29: 352438 | G29: BATERIA YOKO KR 90AMP NX120-7 | H29: Unidad | I29: Unidad | J29: 69715.2
A30: Baterias | B30: Bateria 95 Ah | C30: Talleres / Concesionarios / Flotas | D30: Cristian Hughes | E30: Platin | F30: PT105D31R | G30: 105D31R (90 Ah - 640 CCA) | H30: Unidad | I30: Unidad | J30: 53900 | K30: SI - mas barato
A31: Baterias | B31: Bateria 95 Ah | C31: Talleres / Concesionarios / Flotas | D31: SalfaSur | E31: YOKO G&B | F31: 352438 | G31: BATERIA YOKO KR 90AMP NX120-7 | H31: Unidad | I31: Unidad | J31: 69715.2
A32: Grasas | B32: Grasa alta temperatura | C32: Construccion (mineria) | D32: Vistony | E32: Vistony | F32: 1100198 | G32: CIL COMPLEX MOLY NLGI 2 DE 400 LB | H32: 400 LB | I32: Tambor/Cilindro | J32: 7361 | K32: SI - mas barato
A33: Grasas | B33: Grasa complejo de litio | C33: Flotas | D33: Vistony | E33: Vistony | F33: 1100208 | G33: BAL COMPLEJO DE LITIO NLGI 2 DE 16 KG | H33: 16 KG | I33: Balde | J33: 4681.7 | K33: SI - mas barato
A34: Grasas | B34: Grasa de litio EP2 | C34: Construccion (agro) | D34: Vistony | E34: Vistony | F34: 1100003 | G34: BAL EP-2 LITHIUM MULTIPROPOSITO AMARILLO DE 35 LIBRAS | H34: 35 LIBRAS | I34: Balde | J34: 3874.8 | K34: SI - mas barato
A35: Grasas | B35: Grasa multiproposito EP2 | C35: Talleres / Concesionarios | D35: Vistony | E35: Vistony | F35: 1100140 | G35: TAP EP-2 LITHIUM MULTIPROPOSITO AMARILLO DE 210 GRS | H35: 210 GRS | I35: Tarro | J35: 4395.2 | K35: SI - mas barato
A36: Grasas | B36: Grasa para rodamientos | C36: Industria | D36: Vistony | E36: Vistony | F36: 1100040 | G36: TAP H-3 PARA RODAMIENTOS ROJO DE 453 GRS | H36: 453 GRS | I36: Tarro | J36: 4878.6 | K36: SI - mas barato
A37: Lubricantes | B37: 10W30/10W40 CK-4 | C37: Flotas / Construccion | D37: SalfaSur | E37: AUSTER | F37: 7000012 | G37: AUSTER MAXFORCE 10W40 CK-4 20L | H37: 20 L | I37: Balde | J37: 182.7 | K37: SI - mas barato
A38: Lubricantes | B38: 10W30/10W40 CK-4 | C38: Flotas / Construccion | D38: Vistony | E38: Vistony | F38: 1000153 | G38: CIL TRAKOIL 10W30 DE 55 GAL | H38: 55 GAL | I38: Tambor/Cilindro | J38: 2549.7
A39: Lubricantes | B39: 10W40 semisintetico | C39: Talleres / Concesionarios | D39: SalfaSur | E39: AUSTER | F39: 7000011 | G39: AUSTER MAXFORCE 10W40 CK-4 3L | H39: 3 L | I39: Galon | J39: 1361.8 | K39: SI - mas barato
A40: Lubricantes | B40: 10W40 semisintetico | C40: Talleres / Concesionarios | D40: Vistony | E40: Vistony | F40: 1000807 | G40: GL BLINDAX DUO SAE 10W40 DE 4 LT | H40: 4 LT | I40: Galon | J40: 3033
...

Sheet Recomendacion_por_Segmento
A1: Categoria | B1: Producto (spec) | C1: Segmento | D1: Prioridad | E1: Proveedor recomendado | F1: Marca | G1: Codigo SKU | H1: Presentacion recomendada | I1: Envase | J1: Costo Unitario (CLP) | K1: Margen B2B | L1: Precio B2B sugerido (CLP) | M1: Mercado Min (CLP) | N1: Mercado Max (CLP) | O1: Brecha vs Mercado Min | P1: N Proveedores comparados | Q1: Nota
A2: Baterias | B2: Bateria 45 Ah | C2: Talleres / Concesionarios | D2: Nivel 1 | E2: SalfaSur | F2: YOKO G&B | G2: 352410 | H2: Unidad | I2: Unidad | J2: 31310.5 | K2: =Portada!$D$10 -> 0.35 | L2: =J2/(1-K2) -> 48170 | M2: 54538 | N2: 67227 | O2: =(M2-L2)/M2 -> 0.11676262 | P2: 2
A3: Baterias | B3: Bateria 55 Ah | C3: Talleres / Concesionarios | D3: Nivel 1 | E3: Cristian Hughes | F3: Platin | G3: PT55566 | H3: Unidad | I3: Unidad | J3: 31500 | K3: =Portada!$D$10 -> 0.35 | L3: =J3/(1-K3) -> 48461.538 | M3: 41176 | N3: 79832 | O3: =(M3-L3)/M3 -> -0.17693653 | P3: 2
A4: Baterias | B4: Bateria 60 Ah | C4: Talleres / Concesionarios | D4: Nivel 1 | E4: Cristian Hughes | F4: Platin | G4: PT55566 | H4: Unidad | I4: Unidad | J4: 31500 | K4: =Portada!$D$10 -> 0.35 | L4: =J4/(1-K4) -> 48461.538 | M4: 62941 | N4: 92437 | O4: =(M4-L4)/M4 -> 0.23004816 | P4: 2
A5: Baterias | B5: Bateria 65 Ah | C5: Talleres / Concesionarios | D5: Nivel 1 | E5: Cristian Hughes | F5: Platin | G5: PT55566 | H5: Unidad | I5: Unidad | J5: 31500 | K5: =Portada!$D$10 -> 0.35 | L5: =J5/(1-K5) -> 48461.538 | P5: 2
A6: Baterias | B6: Bateria 70 Ah | C6: Talleres / Concesionarios | D6: Nivel 1 | E6: Cristian Hughes | F6: Platin | G6: PT55D23L | H6: Unidad | I6: Unidad | J6: 40500 | K6: =Portada!$D$10 -> 0.35 | L6: =J6/(1-K6) -> 62307.692 | M6: 63782 | N6: 92437 | O6: =(M6-L6)/M6 -> 0.023114792 | P6: 2
A7: Baterias | B7: Bateria 75 Ah | C7: Talleres / Concesionarios / Flotas | D7: Nivel 1 | E7: Cristian Hughes | F7: Platin | G7: PT85D26L | H7: Unidad | I7: Unidad | J7: 43990 | K7: =Portada!$D$10 -> 0.35 | L7: =J7/(1-K7) -> 67676.923 | M7: 92437 | N7: 100840 | O7: =(M7-L7)/M7 -> 0.26785894 | P7: 2
A8: Baterias | B8: Bateria 80 Ah | C8: Talleres / Concesionarios / Flotas | D8: Nivel 1 | E8: Cristian Hughes | F8: Platin | G8: PT85D26L | H8: Unidad | I8: Unidad | J8: 43990 | K8: =Portada!$D$10 -> 0.35 | L8: =J8/(1-K8) -> 67676.923 | M8: 79748 | N8: 92353 | O8: =(M8-L8)/M8 -> 0.15136526 | P8: 2
A9: Baterias | B9: Bateria 90 Ah | C9: Talleres / Concesionarios / Flotas | D9: Nivel 1 | E9: Cristian Hughes | F9: Platin | G9: PT90D26L | H9: Unidad | I9: Unidad | J9: 52500 | K9: =Portada!$D$10 -> 0.35 | L9: =J9/(1-K9) -> 80769.231 | M9: 83193 | N9: 117815 | O9: =(M9-L9)/M9 -> 0.029134293 | P9: 2
A10: Baterias | B10: Bateria 95 Ah | C10: Talleres / Concesionarios / Flotas | D10: Nivel 1 | E10: Cristian Hughes | F10: Platin | G10: PT105D31R | H10: Unidad | I10: Unidad | J10: 53900 | K10: =Portada!$D$10 -> 0.35 | L10: =J10/(1-K10) -> 82923.077 | P10: 2
A11: Baterias | B11: Bateria 150 Ah | C11: Flotas / Construccion | D11: Nivel 1 | E11: Cristian Hughes | F11: Platin | G11: PT150 | H11: Unidad | I11: Unidad | J11: 104990 | K11: =Portada!$D$10 -> 0.35 | L11: =J11/(1-K11) -> 161523.08 | M11: 142017 | N11: 168067 | O11: =(M11-L11)/M11 -> -0.1373503 | P11: 2
A12: Baterias | B12: Bateria 180 Ah | C12: Flotas / Construccion | D12: Nivel 1 | E12: Cristian Hughes | F12: Platin | G12: PT180 | H12: Unidad | I12: Unidad | J12: 119990 | K12: =Portada!$D$10 -> 0.35 | L12: =J12/(1-K12) -> 184600 | P12: 1
A13: Baterias | B13: Bateria 200 Ah | C13: Flotas / Construccion | D13: Nivel 1 | E13: Cristian Hughes | F13: Platin | G13: PT200 | H13: Unidad | I13: Unidad | J13: 119990 | K13: =Portada!$D$10 -> 0.35 | L13: =J13/(1-K13) -> 184600 | M13: 190336 | N13: 201681 | O13: =(M13-L13)/M13 -> 0.03013618 | P13: 2
A14: Baterias | B14: Bateria 100 Ah | C14: Construccion (agro) | D14: Nivel 2 | E14: Cristian Hughes | F14: Platin | G14: PT105D31R | H14: Unidad | I14: Unidad | J14: 53900 | K14: =Portada!$D$10 -> 0.35 | L14: =J14/(1-K14) -> 82923.077 | M14: 104958 | N14: 126050 | O14: =(M14-L14)/M14 -> 0.20994039 | P14: 2
A15: Baterias | B15: Bateria 120 Ah | C15: Construccion (agro) | D15: Nivel 2 | E15: Cristian Hughes | F15: Platin | G15: PT120 | H15: Unidad | I15: Unidad | J15: 89990 | K15: =Portada!$D$10 -> 0.35 | L15: =J15/(1-K15) -> 138446.15 | P15: 2
A16: Baterias | B16: Bateria 150 Ah agro | C16: Construccion (agro) | D16: Nivel 2 | E16: Cristian Hughes | F16: Platin | G16: PT150 | H16: Unidad | I16: Unidad | J16: 104990 | K16: =Portada!$D$10 -> 0.35 | L16: =J16/(1-K16) -> 161523.08 | P16: 2
A17: Baterias | B17: Bateria 180 Ah agro | C17: Construccion (agro) | D17: Nivel 2 | E17: Cristian Hughes | F17: Platin | G17: PT180 | H17: Unidad | I17: Unidad | J17: 119990 | K17: =Portada!$D$10 -> 0.35 | L17: =J17/(1-K17) -> 184600 | P17: 1
A18: Neumaticos | B18: 185/65R15 | C18: Talleres / Concesionarios | D18: Nivel 1 | E18: SalfaSur | F18: DOUBLE STAR | G18: 210016 | H18: Unidad | I18: Unidad | J18: 26089.1 | K18: =Portada!$D$10 -> 0.35 | L18: =J18/(1-K18) -> 40137.077 | M18: 29412 | N18: 37815 | O18: =(M18-L18)/M18 -> -0.3646497 | P18: 1
A19: Neumaticos | B19: 195/65R15 | C19: Talleres / Concesionarios | D19: Nivel 1 | E19: SalfaSur | F19: KUMHO | G19: 244361 | H19: Unidad | I19: Unidad | J19: 48291.7 | K19: =Portada!$D$10 -> 0.35 | L19: =J19/(1-K19) -> 74294.923 | M19: 50420 | N19: 67227 | O19: =(M19-L19)/M19 -> -0.47352089 | P19: 1
A20: Neumaticos | B20: 205/55R16 | C20: Talleres / Concesionarios | D20: Nivel 1 | E20: SalfaSur | F20: DOUBLE STAR | G20: 210069 | H20: Unidad | I20: Unidad | J20: 29248.2 | K20: =Portada!$D$10 -> 0.35 | L20: =J20/(1-K20) -> 44997.231 | M20: 33613 | N20: 42017 | O20: =(M20-L20)/M20 -> -0.33868535 | P20: 1
A21: Neumaticos | B21: 215/55R17 | C21: Talleres / Concesionarios | D21: Nivel 1 | E21: SIN MATCH | Q21: Sin producto equivalente en el catalogo actual - revisar manualmente
A22: Neumaticos | B22: 225/65R17 | C22: Talleres / Concesionarios | D22: Nivel 1 | E22: SIN MATCH | Q22: Sin producto equivalente en el catalogo actual - revisar manualmente
A23: Neumaticos | B23: 265/65R17 | C23: Flotas / Concesionarios | D23: Nivel 1 | E23: SalfaSur | F23: DOUBLE STAR | G23: 210044 | H23: Unidad | I23: Unidad | J23: 76269.3 | K23: =Portada!$D$10 -> 0.35 | L23: =J23/(1-K23) -> 117337.38 | M23: 79832 | N23: 100840 | O23: =(M23-L23)/M23 -> -0.4698039 | P23: 1
A24: Neumaticos | B24: 265/70R16 | C24: Flotas / Concesionarios | D24: Nivel 1 | E24: SalfaSur | F24: DOUBLE STAR | G24: 210104 | H24: Unidad | I24: Unidad | J24: 66053.4 | K24: =Portada!$D$10 -> 0.35 | L24: =J24/(1-K24) -> 101620.62 | M24: 75630 | N24: 92437 | O24: =(M24-L24)/M24 -> -0.34365484 | P24: 1
A25: Neumaticos | B25: 245/70R16 | C25: Flotas / Concesionarios | D25: Nivel 1 | E25: SalfaSur | F25: DOUBLE STAR | G25: 210103 | H25: Unidad | I25: Unidad | J25: 65589.3 | K25: =Portada!$D$10 -> 0.35 | L25: =J25/(1-K25) -> 100906.62 | M25: 71429 | N25: 88235 | O25: =(M25-L25)/M25 -> -0.41268414 | P25: 1
A26: Neumaticos | B26: 265/60R18 | C26: Flotas / Concesionarios | D26: Nivel 1 | E26: SalfaSur | F26: DOUBLE STAR | G26: 210063 | H26: Unidad | I26: Unidad | J26: 71129.2 | K26: =Portada!$D$10 -> 0.35 | L26: =J26/(1-K26) -> 109429.54 | M26: 117899 | N26: 134706 | O26: =(M26-L26)/M26 -> 0.071836585 | P26: 1
A27: Neumaticos | B27: Tractor 1200 R24 | C27: Construccion (agro) | D27: Nivel 2 | E27: SalfaSur | F27: DOUBLE STAR | G27: 210118 | H27: Unidad | I27: Unidad | J27: 271616.2 | K27: =Portada!$D$10 -> 0.35 | L27: =J27/(1-K27) -> 417871.08 | P27: 1
A28: Neumaticos | B28: Tractor/pulveriz. 245/75R16 | C28: Construccion (agro) | D28: Nivel 2 | E28: SalfaSur | F28: DOUBLE STAR | G28: 210026 | H28: Unidad | I28: Unidad | J28: 69607.4 | K28: =Portada!$D$10 -> 0.35 | L28: =J28/(1-K28) -> 107088.31 | P28: 1
A29: Neumaticos | B29: Camion 295/80R22.5 | C29: Construccion (agro) | D29: Nivel 2 | E29: SalfaSur | F29: DOUBLE STAR | G29: 210067 | H29: Unidad | I29: Unidad | J29: 147103.3 | K29: =Portada!$D$10 -> 0.35 | L29: =J29/(1-K29) -> 226312.77 | P29: 1
A30: Lubricantes | B30: 5W30 sintetico | C30: Talleres / Concesionarios | D30: Nivel 1 | E30: SalfaSur | F30: AUSTER | G30: 7000049 | H30: 4 LT | I30: Galon | J30: 2863.5 | K30: =Portada!$D$10 -> 0.35 | L30: =J30/(1-K30) -> 4405.3846 | P30: 2
A31: Lubricantes | B31: 5W40 sintetico | C31: Talleres / Concesionarios | D31: Nivel 1 | E31: SalfaSur | F31: AUSTER | G31: 7000007 | H31: 3 L | I31: Galon | J31: 1191.9 | K31: =Portada!$D$10 -> 0.35 | L31: =J31/(1-K31) -> 1833.6923 | P31: 2
A32: Lubricantes | B32: 10W40 semisintetico | C32: Talleres / Concesionarios | D32: Nivel 1 | E32: SalfaSur | F32: AUSTER | G32: 7000011 | H32: 3 L | I32: Galon | J32: 1361.8 | K32: =Portada!$D$10 -> 0.35 | L32: =J32/(1-K32) -> 2095.0769 | P32: 2
A33: Lubricantes | B33: 15W40 CI-4 | C33: Flotas / Construccion | D33: Nivel 1 | E33: SalfaSur | F33: AUSTER | G33: 7000007 | H33: 3 L | I33: Galon | J33: 1191.9 | K33: =Portada!$D$10 -> 0.35 | L33: =J33/(1-K33) -> 1833.6923 | P33: 2
A34: Lubricantes | B34: 15W40 CK-4 | C34: Flotas / Construccion | D34: Nivel 1 | E34: SalfaSur | F34: AUSTER | G34: 7000007 | H34: 3 L | I34: Galon | J34: 1191.9 | K34: =Portada!$D$10 -> 0.35 | L34: =J34/(1-K34) -> 1833.6923 | P34: 2
A35: Lubricantes | B35: 10W30/10W40 CK-4 | C35: Flotas / Construccion | D35: Nivel 1 | E35: SalfaSur | F35: AUSTER | G35: 7000012 | H35: 20 L | I35: Balde | J35: 182.7 | K35: =Portada!$D$10 -> 0.35 | L35: =J35/(1-K35) -> 281.07692 | P35: 2
A36: Lubricantes | B36: UTTO | C36: Construccion (agro) | D36: Nivel 2 | E36: SIN MATCH | Q36: Sin producto equivalente en el catalogo actual - revisar manualmente
A37: Lubricantes | B37: STOU | C37: Construccion (agro) | D37: Nivel 2 | E37: SIN MATCH | Q37: Sin producto equivalente en el catalogo actual - revisar manualmente
A38: Lubricantes | B38: Hidraulico ISO 46 | C38: Construccion / Industria | D38: Nivel 2 | E38: SalfaSur | F38: AUSTER | G38: 7000056 | H38: 200 LT | I38: Tambor/Cilindro | J38: 1833.5 | K38: =Portada!$D$10 -> 0.35 | L38: =J38/(1-K38) -> 2820.7692 | P38: 2
A39: Lubricantes | B39: Hidraulico ISO 68 | C39: Construccion / Industria | D39: Nivel 2 | E39: SalfaSur | F39: AUSTER | G39: 7000058 | H39: 200 LT | I39: Tambor/Cilindro | J39: 1845.6 | K39: =Portada!$D$10 -> 0.35 | L39: =J39/(1-K39) -> 2839.3846 | P39: 2
A40: Lubricantes | B40: Hidraulico ISO 32 | C40: Industria | D40: Nivel 3 | E40: SIN MATCH | Q40: Sin producto equivalente en el catalogo actual - revisar manualmente
...

Sheet Resumen_Segmento
A1: RESUMEN POR SEGMENTO — cobertura de catalogo y competitividad vs mercado
A3: Segmento | B3: Productos priorizados | C3: Con match en catalogo | D3: Sin match | E3: Brecha promedio vs Mercado Min | F3: Proveedor mas usado
A4: Concesionarios | B4: 25 | C4: 22 | D4: 3 | E4: -0.1207 | F4: SalfaSur
A5: Construccion | B5: 22 | C5: 20 | D5: 2 | E5: 0.0342 | F5: SalfaSur
A6: Construccion (agro) | B6: 10 | C6: 8 | D6: 2 | E6: 0.2099 | F6: Cristian Hughes
A7: Construccion (mineria) | B7: 1 | C7: 1 | D7: 0 | F7: Vistony
A8: Flotas | B8: 18 | C8: 18 | D8: 0 | E8: -0.0904 | F8: Cristian Hughes
A9: Industria | B9: 7 | C9: 6 | D9: 1 | F9: Vistony
A10: Talleres | B10: 22 | C10: 19 | D10: 3 | E10: -0.0536 | F10: Cristian Hughes

Sheet Notas
A1: COMO SE CONSTRUYO ESTE MODELO
A3: 1. Matriz_Maestra parte de las 653 filas de la Matriz Maestra de Articulos (Cristian Hughes, Vistony, SalfaSur) ya validada, con Tipo, Presentacion, Envase y Precio Unitario calculados por formula.
A5: 2. La hoja Productos_por_Nicho del archivo original del usuario (52 combinaciones producto x segmento, ya priorizadas en Nivel 1/2/3) se uso como la lista maestra de "que se debe vender". Este modelo NO reinventa esa lista — la usa como base y la completa automaticamente con datos reales de la Matriz Maestra.
A7: 3. Para cada uno de esos 52 productos se buscaron TODOS los SKU equivalentes en la Matriz Maestra (por ejemplo "Bateria 45 Ah" se busco en baterias Platin Y en baterias Yoko G&B por amperaje cercano; "5W30 sintetico" se busco por grado SAE en Attom, Sintek y Auster).
A9: 4. De todos los SKU equivalentes encontrados, se filtro por presentacion adecuada al segmento (Talleres/Concesionarios compran formatos chicos: frasco, galon, tarro. Flotas/Construccion/Mineria/Agricola/Industria pueden comprar formatos grandes: bidon, balde, tambor, ademas de los chicos) y se eligio el de menor costo por unidad normalizada (CLP/Litro, CLP/Kg o CLP/Unidad).
A11: 5. Precio B2B sugerido = Costo Unitario / (1 - Margen objetivo, editable en Portada). Se compara contra el precio minimo de mercado ya investigado en la hoja BENCHMARK_Mercado del archivo original (match automatico por categoria y nombre de producto normalizado).
A13: 6. Brecha vs Mercado Min positiva = el precio B2B de RMG queda POR DEBAJO del piso de mercado retail (favorable, hay margen de maniobra). Brecha negativa = el precio B2B calculado ya esta POR ENCIMA del piso retail (revisar margen o proveedor para ese producto).
A15: PRODUCTOS SIN MATCH EN EL CATALOGO ACTUAL (6 de 52) — quedaron marcados en rojo en Recomendacion_por_Segmento:
A16: - Neumaticos 215/55R17 y 225/65R17: medida no disponible en el catalogo Kumho/Double Star/Kenda actual.
A17: - Lubricantes UTTO, STOU e Hidraulico ISO 32: no se identifico un SKU equivalente en Vistony, Cristian Hughes o SalfaSur con esa especificacion exacta.
A18: - Refrigerante azul HOAT: no hay refrigerante azul en el catalogo actual (solo verde, rojo/OAT y formulas heavy-duty).
A19: Accion sugerida: cotizar estos 6 items puntualmente con los proveedores o evaluar si el segmento realmente los necesita en el corto plazo.
... A24: - Brecha vs Mercado solo esta disponible para los productos que ya estaban en la hoja BENCHMARK_Mercado original (28 de 46 productos con match). Los productos nuevos sin benchmark previo no tienen columna de brecha — se recomienda investigar precio de mercado igual que se hizo para los demas.
